Workbook

Sheet PEDIDOS_CLIENTES AUTOMATICO
A10: Data | B10: =TODAY() -> 46110 | G10: ORDEM DE COMPRA CLIENTE
H12: CÓDIGO LUBEFER ( DIGITAR AQUI )
A13: Cliente | B13: =IFERROR(IF($H$13="","",VLOOKUP($H$13,BANCO_DADOS_CLIENTES!A:L,2,0)),"-") | F13: Código do Cliente
A15: Endereço | B15: =IFERROR(IF($H$13="","",VLOOKUP($H$13,BANCO_DADOS_CLIENTES!A:L,3,0)),"-") | E15: Bairro | F15: =IFERROR(IF($H$13="","",VLOOKUP($H$13,BANCO_DADOS_CLIENTES!A:L,5,0)),"-") | H15: Fone | I15: =IFERROR(IF($H$13="","",VLOOKUP($H$13,BANCO_DADOS_CLIENTES!A:L,9,0)),"-")
A17: CNPJ | B17: =IFERROR(IF($H$13="","",VLOOKUP($H$13,BANCO_DADOS_CLIENTES!A:L,8,0)),"-") | D17: Vendedor | E17: =IFERROR(IF($H$13="","",VLOOKUP($H$13,BANCO_DADOS_CLIENTES!A:M,12,0)),"-") | G17: Email | H17: =IFERROR(IF($H$13="","",VLOOKUP($H$13,BANCO_DADOS_CLIENTES!A:L,10,0)),"-")
A20: INSCRIÇÃO ESTADUAL | B20: =IFERROR(IF($H$13="","",VLOOKUP($H$13,BANCO_DADOS_CLIENTES!A:M,13,0)),"-") | E20: Comprador
A22: Cidade | B22: =IFERROR(IF($H$13="","",VLOOKUP($H$13,BANCO_DADOS_CLIENTES!A:L,6,0)),"-") | E22: Estado | F22: =IFERROR(IF($H$13="","",VLOOKUP($H$13,BANCO_DADOS_CLIENTES!A:L,7,0)),"-")
A24: Condições Pagto | G24: ATUALIZAÇÕES | H24: PREÇO BAIXO É BOM, MAS COM QUALIDADE É MELHOR! LUBEFER
C25: N° DE PARCELAS VALORES APROXIMADOS | E25: =IFERROR(H73/D25,"")
A27: Transporte
A29: QUANT. | B29: CÓDIGO LUBEFER | C29: DESCRIÇÃO | G29: NCM CÓDIGO DE BARRA | H29: PREÇO UNITÁRIO | I29: TOTAL | J29: DESCONTO | K29: ENCARTELADO BSP ESPECIAL | L29: IPI | M29: ST
C32: =IFERROR(VLOOKUP(B32,BANCO_DADOS_PEÇAS!B:C,2,0),"") | G32: =IFERROR(VLOOKUP(B32,BANCO_DADOS_PEÇAS!B:H,6,0),"") | H32: =IFERROR(VLOOKUP(B32,BANCO_DADOS_PEÇAS!B:D,3,0)*(100%+K32)*(100%-J32),"") | I32: =IFERROR((IFERROR(H32+(H32*L32)+(H32*M32),H32)*A32),0) -> 0 | L32: =IFERROR(VLOOKUP(B32,BANCO_DADOS_PEÇAS!B:H,7,0),0)/100 -> 0
C33: =IFERROR(VLOOKUP(B33,BANCO_DADOS_PEÇAS!B:C,2,0),"") | G33: =IFERROR(VLOOKUP(B33,BANCO_DADOS_PEÇAS!B:H,6,0),"") | H33: =IFERROR(VLOOKUP(B33,BANCO_DADOS_PEÇAS!B:D,3,0)*(100%+K33)*(100%-J33),"") | I33: =IFERROR((IFERROR(H33+(H33*L33)+(H33*M33),H33)*A33),0) -> 0 | L33: =IFERROR(VLOOKUP(B33,BANCO_DADOS_PEÇAS!B:H,7,0),0)/100 -> 0
C34: =IFERROR(VLOOKUP(B34,BANCO_DADOS_PEÇAS!B:C,2,0),"") | G34: =IFERROR(VLOOKUP(B34,BANCO_DADOS_PEÇAS!B:H,6,0),"") | H34: =IFERROR(VLOOKUP(B34,BANCO_DADOS_PEÇAS!B:D,3,0)*(100%+K34)*(100%-J34),"") | I34: =IFERROR((IFERROR(H34+(H34*L34)+(H34*M34),H34)*A34),0) -> 0 | L34: =IFERROR(VLOOKUP(B34,BANCO_DADOS_PEÇAS!B:H,7,0),0)/100 -> 0
C35: =IFERROR(VLOOKUP(B35,BANCO_DADOS_PEÇAS!B:C,2,0),"") | G35: =IFERROR(VLOOKUP(B35,BANCO_DADOS_PEÇAS!B:H,6,0),"") | H35: =IFERROR(VLOOKUP(B35,BANCO_DADOS_PEÇAS!B:D,3,0)*(100%+K35)*(100%-J35),"") | I35: =IFERROR((IFERROR(H35+(H35*L35)+(H35*M35),H35)*A35),0) -> 0 | L35: =IFERROR(VLOOKUP(B35,BANCO_DADOS_PEÇAS!B:H,7,0),0)/100 -> 0
C36: =IFERROR(VLOOKUP(B36,BANCO_DADOS_PEÇAS!B:C,2,0),"") | G36: =IFERROR(VLOOKUP(B36,BANCO_DADOS_PEÇAS!B:H,6,0),"") | H36: =IFERROR(VLOOKUP(B36,BANCO_DADOS_PEÇAS!B:D,3,0)*(100%+K36)*(100%-J36),"") | I36: =IFERROR((IFERROR(H36+(H36*L36)+(H36*M36),H36)*A36),0) -> 0 | L36: =IFERROR(VLOOKUP(B36,BANCO_DADOS_PEÇAS!B:H,7,0),0)/100 -> 0
C37: =IFERROR(VLOOKUP(B37,BANCO_DADOS_PEÇAS!B:C,2,0),"") | G37: =IFERROR(VLOOKUP(B37,BANCO_DADOS_PEÇAS!B:H,6,0),"") | H37: =IFERROR(VLOOKUP(B37,BANCO_DADOS_PEÇAS!B:D,3,0)*(100%+K37)*(100%-J37),"") | I37: =IFERROR((IFERROR(H37+(H37*L37)+(H37*M37),H37)*A37),0) -> 0 | L37: =IFERROR(VLOOKUP(B37,BANCO_DADOS_PEÇAS!B:H,7,0),0)/100 -> 0
C38: =IFERROR(VLOOKUP(B38,BANCO_DADOS_PEÇAS!B:C,2,0),"") | G38: =IFERROR(VLOOKUP(B38,BANCO_DADOS_PEÇAS!B:H,6,0),"") | H38: =IFERROR(VLOOKUP(B38,BANCO_DADOS_PEÇAS!B:D,3,0)*(100%+K38)*(100%-J38),"") | I38: =IFERROR((IFERROR(H38+(H38*L38)+(H38*M38),H38)*A38),0) -> 0 | L38: =IFERROR(VLOOKUP(B38,BANCO_DADOS_PEÇAS!B:H,7,0),0)/100 -> 0
C39: =IFERROR(VLOOKUP(B39,BANCO_DADOS_PEÇAS!B:C,2,0),"") | G39: =IFERROR(VLOOKUP(B39,BANCO_DADOS_PEÇAS!B:H,6,0),"") | H39: =IFERROR(VLOOKUP(B39,BANCO_DADOS_PEÇAS!B:D,3,0)*(100%+K39)*(100%-J39),"") | I39: =IFERROR((IFERROR(H39+(H39*L39)+(H39*M39),H39)*A39),0) -> 0 | L39: =IFERROR(VLOOKUP(B39,BANCO_DADOS_PEÇAS!B:H,7,0),0)/100 -> 0
C40: =IFERROR(VLOOKUP(B40,BANCO_DADOS_PEÇAS!B:C,2,0),"") | G40: =IFERROR(VLOOKUP(B40,BANCO_DADOS_PEÇAS!B:H,6,0),"") | H40: =IFERROR(VLOOKUP(B40,BANCO_DADOS_PEÇAS!B:D,3,0)*(100%+K40)*(100%-J40),"") | I40: =IFERROR((IFERROR(H40+(H40*L40)+(H40*M40),H40)*A40),0) -> 0 | L40: =IFERROR(VLOOKUP(B40,BANCO_DADOS_PEÇAS!B:H,7,0),0)/100 -> 0
C41: =IFERROR(VLOOKUP(B41,BANCO_DADOS_PEÇAS!B:C,2,0),"") | G41: =IFERROR(VLOOKUP(B41,BANCO_DADOS_PEÇAS!B:H,6,0),"") | H41: =IFERROR(VLOOKUP(B41,BANCO_DADOS_PEÇAS!B:D,3,0)*(100%+K41)*(100%-J41),"") | I41: =IFERROR((IFERROR(H41+(H41*L41)+(H41*M41),H41)*A41),0) -> 0 | L41: =IFERROR(VLOOKUP(B41,BANCO_DADOS_PEÇAS!B:H,7,0),0)/100 -> 0
C42: =IFERROR(VLOOKUP(B42,BANCO_DADOS_PEÇAS!B:C,2,0),"") | G42: =IFERROR(VLOOKUP(B42,BANCO_DADOS_PEÇAS!B:H,6,0),"") | H42: =IFERROR(VLOOKUP(B42,BANCO_DADOS_PEÇAS!B:D,3,0)*(100%+K42)*(100%-J42),"") | I42: =IFERROR((IFERROR(H42+(H42*L42)+(H42*M42),H42)*A42),0) -> 0 | L42: =IFERROR(VLOOKUP(B42,BANCO_DADOS_PEÇAS!B:H,7,0),0)/100 -> 0
C43: =IFERROR(VLOOKUP(B43,BANCO_DADOS_PEÇAS!B:C,2,0),"") | G43: =IFERROR(VLOOKUP(B43,BANCO_DADOS_PEÇAS!B:H,6,0),"") | H43: =IFERROR(VLOOKUP(B43,BANCO_DADOS_PEÇAS!B:D,3,0)*(100%+K43)*(100%-J43),"") | I43: =IFERROR((IFERROR(H43+(H43*L43)+(H43*M43),H43)*A43),0) -> 0 | L43: =IFERROR(VLOOKUP(B43,BANCO_DADOS_PEÇAS!B:H,7,0),0)/100 -> 0
... C72: =IFERROR(VLOOKUP(B72,BANCO_DADOS_PEÇAS!B:C,2,0),"") | G72: =IFERROR(VLOOKUP(B72,BANCO_DADOS_PEÇAS!B:H,6,0),"") | H72: =IFERROR(VLOOKUP(B72,BANCO_DADOS_PEÇAS!B:D,3,0)*(100%+K72)*(100%-J72),"") | I72: =IFERROR((IFERROR(H72+(H72*L72)+(H72*M72),H72)*A72),0) -> 0 | L72: =IFERROR(VLOOKUP(B72,BANCO_DADOS_PEÇAS!B:H,7,0),0)/100 -> 0
A73: OBSERVAÇÕES: | G73: TOTAL | H73: =SUM(I32:I72) -> 0

Sheet BANCO_DADOS_PEÇAS
A1: GRU_CODIGO | B1: PRO_CODIGO | C1: DESCRICAO | D1: PRECO_VENDA_CONSUMIDOR | E1: E_PESOBRT | F1: CODIGO_BARRA | G1: E_CLASFIS | H1: E_IPI | AH1: IPI | AI1: ST
A2: 000 | B2: 005 | C2: ESPIG.FIXO FEMEA 1/4X5/16 LATAO | D2: 4.70799 | E2: 0 | F2: SEM GTIN | G2: 74122000 | H2: 3.25 | AH2: 0.05 | AI2: 0
A3: 000 | B3: BBQ-ONE | C3: SMOKER PORTATIL C/ TAMPA | D3: 150.52 | E3: 5 | F3: SEM GTIN | G3: 73218900 | H3: 6.5 | AH3: 0.05 | AI3: 0
A4: 000 | B4: CAR12 | C4: CARRINHO MULTI FUNCAO BASCULANTE C/ VALV DE ESFERA C/PENEIRA | D4: 1579.4 | E4: 0 | F4: SEM GTIN | G4: 87169090 | H4: 3.25 | AH4: 0.05 | AI4: 0
A5: 000 | B5: CARRO002 | C5: REBOQUERG BRUTOS VTAV-PRETA | D5: 21550.718 | E5: 0 | F5: SEM GTIN | G5: 87163900 | H5: 0 | AH5: 0.05 | AI5: 0
A6: 000 | B6: JAR-01 | C6: ESGUICHO P/MANG.C/ESCAMA DE 1/2 LATAO | D6: 24.91 | E6: 5 | F6: SEM GTIN | G6: 84242000 | H6: 3.25 | AH6: 0.05 | AI6: 0
A7: 000 | B7: LAV31 | C7: ENGATE ADAPTADOR 1/4 PARA LAVADORA X R. MACHO 1/4 BSP LATAO | D7: 15.5396 | E7: 0.015 | F7: SEM GTIN | G7: 84811000 | H7: 0 | AH7: 0.05 | AI7: 0
A8: 000 | B8: LAV32 | C8: ADAPTADOR MACHO M22 TUBO 14 X FEMEA 1/4 BSP LATAO | D8: 9.222 | E8: 0.015 | F8: SEM GTIN | G8: 84811000 | H8: 0 | AH8: 0.05 | AI8: 0
A9: 000 | B9: LAV33 | C9: PINO C/ ORING MACHO 1/4 BSP | D9: 4.8866 | E9: 0.015 | F9: SEM GTIN | G9: 84811000 | H9: 0 | AH9: 0.05 | AI9: 0
A10: 000 | B10: LAV34 | C10: PINO CHANFRADO PRENS.P/ GATILHO KARCHER | D10: 6.0102 | E10: 0.015 | F10: SEM GTIN | G10: 73071920 | H10: 3.25 | AH10: 0.05 | AI10: 0
A11: 000 | B11: LAV35 | C11: PINO FEMEA 1/4 | D11: 6.148 | E11: 0.015 | F11: SEM GTIN | G11: 84811000 | H11: 0 | AH11: 0.05 | AI11: 0
A12: 000 | B12: LAV36 | C12: ENGATE ADAPTADOR 1/4 PARA LAVADORA X R. FEMEA 1/4 LATAO | D12: 15.5396 | E12: 0.015 | F12: SEM GTIN | G12: 84811000 | H12: 0 | AH12: 0.05 | AI12: 0
A13: 000 | B13: LAV37 | C13: ADAPTADOR MACHO M22 TUBO 14 X MACHO 1/4 BSP LATAO | D13: 7.208 | E13: 0.015 | F13: SEM GTIN | G13: 84811000 | H13: 0 | AH13: 0.05 | AI13: 0
... A73: 000 | B73: LUB-1989AC | C73: BICO DE AR P/LIMPEZA EM ALUMINIO CINZA | D73: 23.758654 | E73: 0.074 | F73: SEM GTIN | G73: 84242000 | H73: 3.25 | AH73: 0 | AI73: 0
A74: 000 | B74: LUB-1989AP | C74: BICO DE AR P/LIMPEZA EM ALUMINIO PRETO | D74: 18.709 | E74: 0.072 | F74: 7898310838498 | G74: 84242000 | H74: 3.25 | AI74: 0
A75: 000 | B75: LUB-1989AV | C75: BICO DE AR P/LIMPEZA EM ALUMINIO VERMELHA | D75: 18.709 | E75: 0.074 | F75: 7898310838504 | G75: 84242000 | H75: 3.25 | AH75: 0.05 | AI75: 0
A76: 000 | B76: LUB-1989B | C76: BICO DE AR P/LIMPEZA C/BICO DE NYLON | D76: 16.589 | E76: 0.144 | F76: 7898310835688 | G76: 84242000 | H76: 3.25 | AH76: 0.05 | AI76: 0
A77: 000 | B77: LUB-1989C | C77: BICO DE AR P/LIMPEZA C/BICO DE LATAO | D77: 17.278 | E77: 0.158 | F77: 7898310835695 | G77: 84242000 | H77: 3.25 | AH77: 0.05 | AI77: 0
A78: 000 | B78: LUB-1989D | C78: BICO DE AR P/LIMPEZA C/ HASTE 100MM COMPRIMENTO | D78: 25.387 | E78: 0.158 | F78: SEM GTIN | G78: 84242000 | H78: 3.25 | AH78: 0.05 | AI78: 0
A79: 000 | B79: LUB-1989E | C79: BICO DE AR P/LIMPEZA C/ HASTE 250MM COMPRIMENTO | D79: 25.811 | E79: 0.158 | F79: SEM GTIN | G79: 84242000 | H79: 3.25 | AH79: 0.05 | AI79: 0
A80: 000 | B80: LUB-1989NA | C80: BICO DE AR P/LIMPEZA EM NYLON AZUL | D80: 12.19 | E80: 0.074 | F80: SEM GTIN | G80: 84242000 | H80: 3.25 | AH80: 0.05 | AI80: 0
A81: 000 | B81: LUB-1989NP | C81: BICO DE AR P/LIMPEZA EM NYLON PRETO | D81: 12.19 | E81: 0.074 | F81: SEM GTIN | G81: 84242000 | H81: 3.25 | AH81: 0 | AI81: 0
A82: 000 | B82: LUB-1989NV | C82: BICO DE AR P/LIMPEZA EM NYLON VERMELHA | D82: 12.19 | E82: 0.074 | F82: SEM GTIN | G82: 84242000 | H82: 3.25 | AH82: 0 | AI82: 0
A83: 000 | B83: LUB-1990 | C83: PONTA DO BICO DE AR REG ALTA VAZAO BAIXO RUIDO | D83: 9.4234 | E83: 0.144 | F83: SEM GTIN | G83: 84242000 | H83: 3.25 | AH83: 0 | AI83: 0
A84: 000 | B84: LUB-1992AA | C84: PULVERIZADOR PNEUMATICO EM ALUMINIO AZUL | D84: 22.048 | E84: 0.1236 | F84: 7898310838535 | G84: 84242000 | H84: 3.25 | AH84: 0 | AI84: 0
A85: 000 | B85: LUB-1992AC | C85: PULVERIZADOR PNEUM. EM ALUMINIO CINZA | D85: 26.762085 | E85: 0.12 | F85: SEM GTIN | G85: 84242000 | H85: 3.25 | AH85: 0 | AI85: 0
A86: 000 | B86: LUB-1992AP | C86: PULVERIZADOR PNEUMATICO EM ALUMINIO PRETO | D86: 22.048 | E86: 0.12 | F86: 7898310838511 | G86: 84242000 | H86: 3.25 | AH86: 0 | AI86: 0
... A286: 000 | B286: LUB-2040K | C286: ESG. SUPER LONGO P/JARDIM C/ PINO ACOPLAVEL P/ 2040E | D286: 54.7278 | E286: 0.296 | F286: 7898310839914 | G286: 84242000 | H286: 3.25 | AH286: 0.05 | AI286: 0
A287: 000 | B287: LUB-2040L | C287: BICO DE ESGUICHO REG P/LAVADORA ALTA PRESSAO FURO 1MM | D287: 33.92 | F287: SEM GTIN | G287: 84242000 | H287: 3.25 | AH287: 0.05 | AI287: 0
A288: 000 | B288: LUB-2040LP | C288: BICO ESGUICHO REG P/LAVADORA DE ALTA PRESSAO FURO 1.2MM PRO | D288: 33.92 | F288: SEM GTIN | G288: 84242000 | H288: 3.25 | AH288: 0.05 | AI288: 0
A289: 000 | B289: LUB-2050 | C289: ENGATE RAP. HIDRAUL. INDL. DE 1/2 | D289: 53.265 | E289: 0.344 | F289: 7898310837576 | G289: 84811000 | H289: 0 | AH289: 0.05 | AI289: 0
A290: 000 | B290: LUB-2050-1 | C290: PINO DE ENG.HIDR. INDL. 1/2 R. FEMEA | D290: 24.1892 | E290: 0.108 | F290: 7898310837811 | G290: 84811000 | H290: 0 | AH290: 0.05 | AI290: 0
A291: 000 | B291: LUB-2050H | C291: ENGATE RAP. AGRIC. DE 1/2 HIDRAUL. | D291: 43.1526 | E291: 0.304 | F291: 7898310837583 | G291: 84811000 | H291: 0 | AH291: 0.05 | AI291: 0
A292: 000 | B292: LUB-2050H1 | C292: PINO DE ENG.HIDR. R.F. 1/2 AGRICOLA | D292: 23.0338 | E292: 0.088 | F292: 7898310837705 | G292: 84811000 | H292: 0 | AH292: 0.05 | AI292: 0
A293: 000 | B293: LUB-2050HA | C293: ENGATE RAP.HIDRAULICO 1/2 R.MACHO M22 (TRATORES JOHN DERRE) | D293: 96.4176 | E293: 0.554 | F293: 7898310839068 | G293: 84811000 | H293: 0 | AH293: 0.05 | AI293: 0
A294: 000 | B294: LUB-2050HB | C294: ENGATE RAP.HIDRAULICO 1/2 R.MACHO 1/2 (TRATORES NEW HOLAND) | D294: 96.4176 | E294: 0.544 | F294: 7898310839860 | G294: 84811000 | H294: 0 | AH294: 0.05 | AI294: 0
A295: 000 | B295: LUB-2050HC | C295: ENGATE RAP.HIDRAULICO 1/2 R.MACHO 3/4 UNF (TRATORES VALMET) | D295: 96.4176 | E295: 0.548 | F295: 7898310839631 | G295: 84811000 | H295: 0 | AH295: 0.05 | AI295: 0
A296: 000 | B296: LUB-2050HD | C296: ENGATE RAP.HIDRAULICO 1/2 R.MACHO 7/8 UNF (TRATORES MASSEY F | D296: 96.4176 | E296: 0.544 | F296: 7898310839501 | G296: 84811000 | H296: 0 | AH296: 0.05 | AI296: 0
A297: 000 | B297: LUB-2050HE | C297: ENGATE RAP.HIDRAULICO 1/2 R.MACHO 1.1/16 UNF | D297: 109.2754 | E297: 0.544 | F297: SEM GTIN | G297: 84811000 | H297: 0 | AH297: 0.05 | AI297: 0
A298: 000 | B298: LUB-2050HF | C298: ENGATE RAP.HIDRAULICO 1/2 R.MACHO 13/16 UNF | D298: 109.2754 | E298: 0.544 | F298: SEM GTIN | G298: 84811000 | H298: 0 | AH298: 0.05 | AI298: 0
...

Sheet IPI SP
A1: CÓDIGO | B1: DESCRIÇÃO | C1: NCM | D1: IPI
A2: LUB-5D3 | B2: FLANGE DISCO LIXA 4.1/2 ROSCA FEMEA M14 | C2: 39172900 | D2: 0
A3: LUB-5D3 | B3: FLANGE DISCO LIXA 4.1/2 ROSCA FEMEA M14 | C3: 39172900 | D3: 0
A4: LUB-5D4 | B4: FLANGE DISCO LIXA 7 - ROSCA FEMEA M14 | C4: 39172900 | D4: 0
A5: LUB-5D4 | B5: FLANGE DISCO LIXA 7 - ROSCA FEMEA M14 | C5: 39172900 | D5: 0
A6: LUB-5D5 | B6: FLANGE PARA ESMERILHADEIRA 4P E 7P | C6: 39172900 | D6: 0
A7: LUB-5D6 | B7: CHAVE COM PINOS P/ SACAR FLANGE/PORCA ESMERILHADEIRA | C7: 39172900 | D7: 0
A8: LUB-5D6-C | B8: CHAVE COM PINOS P/ SACAR FLANGE/PORCA ESMERILHADEIRA COMBAT | C8: 39172900 | D8: 0
A9: LUB-LAV03 | B9: CAPA-PORCA ESGUICHO ALTA PRESSAO (SUPORTE GICLE) | C9: 39172900 | D9: 0
A10: LUB-LAV03 | B10: CAPA-PORCA ESGUICHO ALTA PRESSAO (SUPORTE GICLE) | C10: 39172900 | D10: 0
A11: LUB-2053 | B11: MANGUEIRA P/ ASPIR. DE PO DE 2 CINZA | C11: 39173100 | D11: 0
A12: LUB-2053 | B12: MANGUEIRA P/ ASPIR. DE PO DE 2 CINZA | C12: 39173100 | D12: 0
A13: LUB-2053A | B13: MANGUEIRA P/ ASPIR. DE PO DE 1.1/2 CINZA | C13: 39173100 | D13: 0
... A328: LUB-FLX29E | B328: MANG.FLEX1/2 550MM TM M F M16 X 1,5 M G M16 X 1,5 CAR MOD | C328: 39173100 | D328: 0.05
B329: MANGUEIRA ESPIRAL C/ 15,00 MTS. C/TERM. | C329: 39173100 | D329: 0.05
A330: LUB-TAP | B330: KIT PROTETOR DE ROSCA M/F P/ENG.AGRIC. 1/2 | C330: 39235000 | D330: 0.05
A331: 004 | B331: . | C331: 40092190 | D331: 0.1
A332: 120 | B332: EXTENS.FLEX.500MM 1/4 X 1/8 MACHO | C332: 40092190 | D332: 0.1
A333: LUB-100 | B333: EXT.FLEX. 1/4 300MM TERM. 1/8 MACHO NPT | C333: 40092190 | D333: 0.1
A334: LUB-100 | B334: EXTENS.FLEX. 1/4 C/ 300MM TERMINAL 1/8 MACHO | C334: 40092190 | D334: 0.1
A335: LUB-100 | B335: EXTENS.FLEX.300MM 1/4 X 1/8 MACHO | C335: 40092190 | D335: 0.1
A336: LUB-1000 | B336: MANG.P/BALDE MAN.DE GRAXA 10 MTS 1 TRAMA SEM TERMINAIS | C336: 40092190 | D336: 0.1
A337: LUB-1000 | B337: MANG.P/BALDE MAN.DE GRAXA 10 MTS 1 TRAMA SEM TERMINAIS | C337: 40092190 | D337: 0.1
A338: LUB-100-1 | B338: EXTENS.FLEX. 1/4 C/ 400MM TERMINAL 1/8 MACHO | C338: 40092190 | D338: 0.1
A339: LUB-100-2 | B339: EXTENSAO FLEXIVEL 470 MM 1/4 NPT X 1/4 NPT | C339: 40092190 | D339: 0.1
A340: LUB-100-3 | B340: EXTENSAO FLEXIVEL 650 MM 1/4 NPT X 1/4 NPT | C340: 40092190 | D340: 0.1
A341: LUB-100-4 | B341: EXTENSAO FLEXIVEL 840 MM 1/4 NPT X 1/8 NPT | C341: 40092190 | D341: 0.1
... A3901: LUB-52Z1 | B3901: ABRACADEIRA DE FITA 127 mm X 146 mm | C3901: 73261900 | D3901: 0
B3902: BUCHA 1/4 MACHO X 1/8 FEMEA LATAO | C3902: 74122000 | D3902: 0.05
A3903: 002 | B3903: ESPIG.FIXO MACHO ROSCA 1 X1/2 LT 50 MM | C3903: 74122000 | D3903: 0.05
A3904: 005 | B3904: ESPIG.FIXO FEMEA 1/4X5/16 LATAO | C3904: 74122000 | D3904: 0.05
A3905: LUB-1014-L | B3905: DES.213001 ADAPT.FILTRO PARKER R.M.1/2 C/LATERAL R.F.3/8 | C3905: 74122000 | D3905: 0.05
A3906: LUB-1014-L | B3906: DES.213001 ADAPT.FILTRO PARKER R.M.7/8 C/LATERAL R.F.3/8 | C3906: 74122000 | D3906: 0.05
A3907: LUB-1030L1 | B3907: ADAPT MANIFOLD M 7/16 UNF X FRM 9/16 UNF LAT | C3907: 74122000 | D3907: 0.05
A3908: LUB-10B | B3908: GICLE ESGUICHO REGULAVEL FURO 0,95 MM | C3908: 74122000 | D3908: 0.05
A3909: LUB-10B | B3909: GICLE ESGUICHO REGULAVEL FURO 0,95 MM | C3909: 74122000 | D3909: 0.05
A3910: LUB-10C | B3910: GICLE ESGUICHO REGULAVEL FURO 1,0 MM | C3910: 74122000 | D3910: 0.05
A3911: LUB-10C | B3911: GICLE ESGUICHO REGULAVEL FURO 1,0 MM | C3911: 74122000 | D3911: 0.05
A3912: LUB-10D | B3912: GICLE ESGUICHO REGULAVEL FURO 1,5 MM | C3912: 74122000 | D3912: 0.05
A3913: LUB-10D | B3913: GICLE ESGUICHO REGULAVEL FURO 1,5 MM | C3913: 74122000 | D3913: 0.05
...

Sheet IPI MG
A1: CÓDIGO | B1: DESCRIÇÃO | C1: NCM | D1: IPI
A2: LUB-5D3 | B2: FLANGE DISCO LIXA 4.1/2 ROSCA FEMEA M14 | C2: 39172900 | D2: 0
A3: LUB-5D4 | B3: FLANGE DISCO LIXA 7 - ROSCA FEMEA M14 | C3: 39172900 | D3: 0
A4: LUB-5D5 | B4: FLANGE PARA ESMERILHADEIRA 4P E 7P | C4: 39172900 | D4: 0
A5: LUB-5D6 | B5: CHAVE COM PINOS P/ SACAR FLANGE/PORCA ESMERILHADEIRA | C5: 39172900 | D5: 0
A6: LUB-5D6-C | B6: CHAVE COM PINOS P/ SACAR FLANGE/PORCA ESMERILHADEIRA COMBAT | C6: 39172900 | D6: 0
A7: LUB-LAV03 | B7: CAPA-PORCA ESGUICHO ALTA PRESSAO (SUPORTE GICLE) | C7: 39172900 | D7: 0
A8: LUB-2053 | B8: MANGUEIRA P/ ASPIR. DE PO DE 2 CINZA | C8: 39173100 | D8: 0
A9: LUB-2053A | B9: MANGUEIRA P/ ASPIR. DE PO DE 1.1/2 CINZA | C9: 39173100 | D9: 0
A10: LUB-2056 | B10: MANGUEIRA DE AR P/COMPRES.1/4 PRETA | C10: 39173100 | D10: 0
A11: LUB-2056A | B11: MANGUEIRA DE AR P/COMPRES.5/16 PRETA | C11: 39173100 | D11: 0
A12: LUB-2056B | B12: MANGUEIRA DE AR P/COMPRES.3/8 PRETA | C12: 39173100 | D12: 0
A13: LUB-2056C | B13: MANGUEIRA DE AGUA P/ALTA PRESSAO 1/2 AZUL | C13: 39173100 | D13: 0
... A256: LUB-FLX29E | B256: MANG.FLEX1/2 550MM TM M F M16 X 1,5 M G M16 X 1,5 CAR MOD | C256: 39173100 | D256: 0.05
B257: MANGUEIRA ESPIRAL C/ 15,00 MTS. C/TERM. | C257: 39173100 | D257: 0.05
A258: LUB-TAP | B258: KIT PROTETOR DE ROSCA M/F P/ENG.AGRIC. 1/2 | C258: 39235000 | D258: 0.05
A259: 004 | B259: . | C259: 40092190 | D259: 0.1
A260: 120 | B260: EXTENS.FLEX.500MM 1/4 X 1/8 MACHO | C260: 40092190 | D260: 0.1
A261: LUB-100 | B261: EXTENS.FLEX. 1/4 C/ 300MM TERMINAL 1/8 MACHO | C261: 40092190 | D261: 0.1
A262: LUB-100 | B262: EXTENS.FLEX.300MM 1/4 X 1/8 MACHO | C262: 40092190 | D262: 0.1
A263: LUB-1000 | B263: MANG.P/BALDE MAN.DE GRAXA 10 MTS 1 TRAMA SEM TERMINAIS | C263: 40092190 | D263: 0.1
A264: LUB-1000 | B264: MANG.P/BALDE MAN.DE GRAXA 10 MTS 1 TRAMA SEM TERMINAIS | C264: 40092190 | D264: 0.1
A265: LUB-100-1 | B265: EXTENS.FLEX. 1/4 C/ 400MM TERMINAL 1/8 MACHO | C265: 40092190 | D265: 0.1
A266: LUB-100-2 | B266: EXTENSAO FLEXIVEL 470 MM 1/4 NPT X 1/4 NPT | C266: 40092190 | D266: 0.1
A267: LUB-100-3 | B267: EXTENSAO FLEXIVEL 650 MM 1/4 NPT X 1/4 NPT | C267: 40092190 | D267: 0.1
A268: LUB-100-4 | B268: EXTENSAO FLEXIVEL 840 MM 1/4 NPT X 1/8 NPT | C268: 40092190 | D268: 0.1
A269: LUB-100-5 | B269: EXTENSAO FLEXIVEL 870 MM 1/4 NPT X 1/8 NPT | C269: 40092190 | D269: 0.1
... A3638: LUB-52Z1 | B3638: ABRACADEIRA DE FITA 127 mm X 146 mm | C3638: 73261900 | D3638: 0
B3639: BUCHA 1/4 MACHO X 1/8 FEMEA LATAO | C3639: 74122000 | D3639: 0.05
A3640: 002 | B3640: ESPIG.FIXO MACHO ROSCA 1 X1/2 LT 50 MM | C3640: 74122000 | D3640: 0.05
A3641: 005 | B3641: ESPIG.FIXO FEMEA 1/4X5/16 LATAO | C3641: 74122000 | D3641: 0.05
A3642: LUB-1014-L | B3642: DES.213001 ADAPT.FILTRO PARKER R.M.1/2 C/LATERAL R.F.3/8 | C3642: 74122000 | D3642: 0.05
A3643: LUB-1014-L | B3643: DES.213001 ADAPT.FILTRO PARKER R.M.7/8 C/LATERAL R.F.3/8 | C3643: 74122000 | D3643: 0.05
A3644: LUB-1030L1 | B3644: ADAPT MANIFOLD M 7/16 UNF X FRM 9/16 UNF LAT | C3644: 74122000 | D3644: 0.05
A3645: LUB-10B | B3645: GICLE ESGUICHO REGULAVEL FURO 0,95 MM | C3645: 74122000 | D3645: 0.05
A3646: LUB-10B | B3646: GICLE ESGUICHO REGULAVEL FURO 0,95 MM | C3646: 74122000 | D3646: 0.05
A3647: LUB-10C | B3647: GICLE ESGUICHO REGULAVEL FURO 1,0 MM | C3647: 74122000 | D3647: 0.05
A3648: LUB-10C | B3648: GICLE ESGUICHO REGULAVEL FURO 1,0 MM | C3648: 74122000 | D3648: 0.05
A3649: LUB-10D | B3649: GICLE ESGUICHO REGULAVEL FURO 1,5 MM | C3649: 74122000 | D3649: 0.05
A3650: LUB-10D | B3650: GICLE ESGUICHO REGULAVEL FURO 1,5 MM | C3650: 74122000 | D3650: 0.05
...

Sheet BANCO_DADOS_CLIENTES
A1: K_COD | B1: K_RAZAO | C1: K_ENDFIS | D1: K_NUMFIS | E1: K_BAIFIS | F1: K_MUNFIS | G1: K_ESTFIS | H1: K_CGCFIS | I1: K_FONECON | J1: K_EMAIL | K1: K_OBSPED | L1: NOME | M1: K_IEFIS | N1: TRANSPORTE
A2: 00000 | B2: DIVERSOS CLIENTES | C2: DIVERSOS CLIENTES | D2: 0 | E2: ...... | G2: PR | H2: 00.000.000/0000-00 | J2: vendas@lubefer.com.br | L2: ADMINISTRACAO | M2: ..................
A3: 00003 | B3: UNIBORRACHAS UNIAO COML BORR. LTDA-MTZ | C3: AV. FLORIANO PEIXOTO, | D3: 3731 | E3: B. BRASIL | F3: UBERLANDIA | G3: MG | H3: 41.688.037/0001-31 | I3: 3432329335 | J3: rafael@uniborrachas.com.br | L3: NETO OLIVEIRA | M3: 702.782.004.0077
A4: 00007 | B4: COML. RODRIGUES NETO TINTAS LTDA-ME | C4: AV. ARGENTINA. 173 | D4: 173 | E4: PQ. PARAISO | F4: ITAPECERICA DA SERRA | G4: SP | H4: 00.833.437/0001-06 | J4: netotinta@gmail.com | L4: CLAUDIO THEODORO | M4: 370098730114
A5: 00009 | B5: CEMA COMERCIO E MANUTENCAO LTDA. | C5: AV. VASCONCELOS COSTA, | D5: 493 | E5: MARTINS | F5: UBERLANDIA | G5: MG | H5: 17.097.973/0001-93 | I5: (34)3236-9318 | J5: cema@hotmail.com; cemacomercio@hotmail.com | L5: NETO OLIVEIRA | M5: 702.052.826.0066
A6: 00010 | B6: LOJAS DOMINICK LTDA. | C6: RUA SANTOS SARAIVA, | D6: 451 | E6: ESTREITO | F6: FLORIANOPOLIS | G6: SC | H6: 83.873.935/0001-00 | I6: (48)2106-2300 | J6: fernando@lojadominik.com.br | K6: TS NORMAL ATE DEZ/2014 | L6: VIG | M6: 250.048.108
A7: 00013 | B7: DECK COMERCIO E SERVICOS LTDA. | C7: RUA MARIA CANDIDA, | D7: 85 | E7: VILA GUILHERME | F7: SAO PAULO | G7: SP | H7: 43.569.649/0001-30 | I7: 3384-8517 | J7: ADEMARDECK@GMAIL.COM | L7: CLAUDIO ANDREANI | M7: 110.331.000.112
A8: 00014 | B8: CARIM FERRAMENTAS EIRELI | C8: RUA BRIGADEIRO GALVAO LOJA 97 | D8: 91 | E8: BARRA FUNDA | F8: SAO PAULO | G8: SP | H8: 62.954.680/0001-30 | I8: 11-3825-0555 | J8: carimferramentas@hotmail.com | K8: SMP 35 DDL /HORARIO DE ALMOCO 11H AS 13H | L8: ROBERTO P. | M8: 108.424.733.116
A9: 00015 | B9: MARCO BOTTEON IND. E COM. LTDA. | C9: AV. EUCLIDES MIRAGAIA, | D9: 2445 | E9: CENTRO | F9: BIRIGUI | G9: SP | H9: 45.381.837/0001-66 | I9: (18)3643-1000 | J9: alexandre@botteon.com.br;botteon@botteon.com.br | L9: ROMUALDO | M9: 214.004.645.113
A10: 00018 | B10: PROPOSTO COM DE EQUIPS E ACESS LTDA | C10: RUA DR. CARVALHO CHAVES, | D10: 534 | E10: PAROLIN | F10: CURITIBA | G10: PR | H10: 81.049.827/0001-91 | I10: (41)3332-2754 | J10: adm3@proposto.com.br; compras@proposto.com.br | K10: SEM ST - CONS FISCAL | L10: M.A. CASTRO | M10: 101.703.92.41
A11: 00025 | B11: PARAFUSOS SAO PAULO LTDA | C11: AV. CALOGERAS, | D11: 1435 | E11: CENTRO | F11: CAMPO GRANDE | G11: MS | H11: 24.658.841/0001-59 | I11: (67) 3382-3268 | J11: compras@parafusossaopaulo.com.br | K11: compras@parafusossaopaulo.com.br | L11: GUGI / DACIO | M11: 28.255.070.4
A12: 00026 | B12: ITAPAR LTDA | C12: RUA BLUMENAU, | D12: 756 | E12: CENTRO | F12: ITAJAI | G12: SC | H12: 01.132.443/0001-07 | I12: (47) 3348-1040 | L12: VIG | M12: 253.245.311
A13: 00028 | B13: PEDRO O. MENDEZ E CIA. LTDA. | C13: RUA ANIBAL VENTURINI | D13: 303 | E13: LUCAS ARAUJO | F13: PASSO FUNDO | G13: RS | H13: 92.147.271/0001-92 | I13: (54) 3313-1774 | J13: pedro.o.mendez@hotmail.com | L13: ADMINISTRACAO | M13: 091.0114285
A14: 00030 | B14: FERBRASA FERRAMENTAS DO BRASIL LTDA | C14: C-03 LOTE 17 LOJA 02 | D14: 0 | E14: CENTRO | F14: TAGUATINGA | G14: DF | H14: 37.072.782/0001-84 | I14: (61)3351-9933 | J14: ferdinando9001@hotmail.com | L14: ADMINISTRACAO | M14: 07.308.940001.75
A15: 00036 | B15: COMERCIO QUINTINO MAQS. E FERRS. LTDA. | C15: AV. AFONSO PENA | D15: 3580 | E15: BRASIL | F15: UBERLANDIA | G15: MG | H15: 25.945.031/0001-46 | I15: 34-3232-1960 | J15: leonardo@quintinoferramentas.com | L15: NETO OLIVEIRA | M15: 702.628.883.0020
A16: 00043 | B16: ANG EQUIPAMENTOS LTDA | C16: AV. JK, | D16: 516 | E16: VILA BRETAS | F16: GOVERNADOR VALADARES | G16: MG | H16: 18.330.373/0001-96 | I16: (33)3279-3200 | J16: karina@angequipamentos.com.br | L16: CWP REPRES | M16: 2771523090075
A17: 00045 | B17: A.C. COMERCIO DE FERRAMENTAS LTDA. | C17: AV. SERAFIM GONCALVES PEREIRA, | D17: 473 | E17: PQ NOVO MUNDO | F17: SAO PAULO | G17: SP | H17: 51.167.369/0001-24 | J17: acferramentas@acferramentas.com.br | K17: MANDAR 2000 SEM ENCARTELAR | L17: ANDERSON CERQUEIRA SILVA | M17: 110.100.036.113
A18: 00046 | B18: ALFREDO PECAS E ACES P AUT LTDA EPP | C18: AV. CAMPOS SALLES, | D18: 132 | E18: CENTRO | F18: SANTOS | G18: SP | H18: 44.981.702/0001-79 | I18: (13) 3232-9445 | J18: alfredobaterias@uol.com.br | K18: TRANSPORTADORA GR EXPRESS | L18: CLAUDIO THEODORO | M18: 633.103.588.114
A19: 00049 | B19: AIR WEST COMPRESSORES LTDA EPP | C19: R FAUSTOLO, | D19: 980 | E19: VILA ROMANA | F19: SAO PAULO | G19: SP | H19: 72.937.188/0001-00 | I19: 11-3865-7182 | J19: vendas@airwestcompressores.com.br | L19: CLAUDIO THEODORO | M19: 113.923.813.113
A20: 00051 | B20: AGROSA MAQUINAS E MOTORES LTDA. | C20: RUA PADRE CASSEMIRO, | D20: 650 | E20: CENTRO | F20: CACERES | G20: MT | H20: 37.511.201/0001-63 | I20: (65)3223-1593 | J20: jiboia_koji@hotmail.com | L20: ARI | M20: 13.143.315.6
A21: 00052 | B21: AGRO OESTE COMERCIAL LTDA | C21: AV. DOS TARUMAS, CX P. 79 | D21: 429 | E21: JD. BOTANICO | F21: SINOP | G21: MT | H21: 15.004.997/0001-25 | I21: (66)3531-2782 | J21: elvio@mfzanini.com.br | K21: CNAE PRINC 4661-3/00 NÃO TEM ST | L21: ARI | M21: 13.113.355.1
A22: 00053 | B22: AGRO FERRAGENS LUIZAO LTDA. | C22: AV. FERNANDO CORREIA DA COSTA, | D22: 1118 | E22: CENTRO | F22: RONDONOPOLIS | G22: MT | H22: 24.774.390/0001-15 | I22: (66)3439-2000 | J22: fiscal@luizao.com.br | K22: ENCARTELADO | L22: PELINSON REPRES | M22: 13.071.742.8
A23: 00055 | B23: ADAMS & CIA LTDA | C23: RUA SAO PAULO, | D23: 2087 | E23: CENTRO | F23: CASCAVEL | G23: PR | H23: 78.799.723/0001-90 | I23: (45)3225.2818 | L23: E.S.PEREIRA/EDSON | M23: 410.08504.65
A24: 00059 | B24: ACARAY COM MANGS CONEXOES HIDR LTDA | C24: AV PRES TANCREDO NEVES | D24: 399 | E24: CENTRO | F24: CASCAVEL | G24: PR | H24: 79.554.168/0001-07 | I24: 4532243735 | J24: financeiro@acaraycascavel.com.br | L24: M.A. CASTRO | M24: 4100119213
A25: 00060 | B25: ABRAMAQ COM ABRASIVOS E MAQ EIRELI | C25: TV HUGO FREITAS | D25: 50 | E25: VILA PORTES | F25: FOZ DO IGUACU | G25: PR | H25: 79.576.237/0001-75 | I25: (45)3528-9500 | J25: abramaqnfe@yahoo.com.br | L25: DALSSASO/MARCO | M25: 42.200.847.07
A26: 00062 | B26: A VITORIOSA EQUIPS P/ LUBRIFICACAO LTDA | C26: AV. GETULIO DE MOURA, | D26: 3558 | E26: PRES. JUSCELINO | F26: MESQUITA | G26: RJ | H26: 73.957.284/0001-82 | I26: (21)2796-6874 | J26: avitoriosaltda@gmail.com; danielerossetto@hotmail.com | K26: SO A VISTA ANTECIPADO | L26: ALBAMAR/NILTON | M26: 85.141.325
A27: 00063 | B27: A MILIMETRICA PARAFUSOS E FERR. LTDA | C27: AV. AZENHA, | D27: 616 | E27: AZENHA | F27: PORTO ALEGRE | G27: RS | H27: 72.265.721/0001-34 | J27: amilimetrica@amilimetrica.com.br | L27: ALFA REPRES. | M27: 096.2350583
A28: 00066 | B28: ANT FERRAMENTAS COML E IMPORT. LTDA | C28: RUA PIRATININGA, | D28: 832 | E28: BRAS | F28: SAO PAULO | G28: SP | H28: 74.671.991/0001-70 | I28: (11)3345-3200 | J28: financeiro@antferramentas.com.br;compras@antferramentas.com.br | L28: ANDERSON CERQUEIRA SILVA | M28: 114.005.696.113
A29: 00067 | B29: A.N.L. PARAFUSOS E FERRAMENTAS LTDA | C29: AV. CRUZEIRO DO SUL, | D29: 2611 | E29: SANTANA | F29: SAO PAULO | G29: SP | H29: 60.985.587/0001-67 | I29: (11)2221-5066 | J29: anl@anl.com.br | L29: ANDERSON CERQUEIRA SILVA | M29: 105.187.243.114
A30: 00070 | B30: AUTO PECAS JOAQUINENSE LTDA EPP | C30: RUA GOIAS , | D30: 1551 | E30: CENTRO | F30: SAO JOAQUIM DA BARRA | G30: SP | H30: 44.258.978/0001-23 | I30: (16)3818-0544 | J30: apjoaquinense@netsite.com.br | L30: VICENTE/VPR | M30: 642.010.844.110
A31: 00072 | B31: AUTO LUB MANUTENCAO E COMERCIO LTDA | C31: RUA CERINA, | D31: 201 | E31: ALTO DOS PINHEIROS | F31: BELO HORIZONTE | G31: MG | H31: 23.885.544/0001-83 | J31: rodrigoautolub@yahoo.com.br | L31: ADMINISTRACAO | M31: 062.569.020.0068
A32: 00075 | B32: PARAFUSOS CAME LTDA - ME | C32: R. COLONIZADOR ENIO PIPINO, 52-53 | D32: 52 | E32: INDUSTRIAL NORTE | F32: SINOP | G32: MT | H32: 05.517.762/0001-83 | I32: 6635312896 | J32: parafusoscame@ig.com.br | L32: ARI | M32: 13.349.411.0
A33: 00085 | B33: ROSELI RODRIGUES MORAES COMERCIO | C33: AV. DUQUE DE CAXIAS, CXPST 1519 | D33: 386 | E33: MARRECAS | F33: FRANCISCO BELTRAO | G33: PR | H33: 81.492.092/0001-76 | J33: arbel@wln.com.br | L33: ADMINISTRACAO | M33: 321.024.092.5
A34: 00088 | B34: ARAGUAIA PECAS E IMPL. AGRIC. LTDA | C34: AV. CONEGO JOAO LIMA, | D34: 34 | E34: ENTRONCAMENTO | F34: ARAGUAINA | G34: TO | H34: 02.399.921/0001-02 | I34: (63) 3415-2020 | J34: apiagril@hotmail.com | L34: RIBEIRO & PIMENTEL | M34: 29.000.575.2
A35: 00092 | B35: ASSISTENCIA MEC HIDRAUL GOIAS LTDA EPP | C35: RUA P 16, 204 | D35: 0 | E35: SETOR FUNCIONARIOS | F35: GOIANIA | G35: GO | H35: 02.665.586/0001-39 | I35: 62-3233.4800 | J35: amhigomatriz@terra.com.br | L35: ENIO SILVA | M35: 10.040.995.4
A36: 00094 | B36: ALPRENA COM. MATERIAL P/ SOLDA LTDA. | C36: AV. PATRICIO LIMA, | D36: 625 | E36: HUMAITA | F36: TUBARAO | G36: SC | H36: 81.390.619/0001-51 | I36: (48) 3622-2233 | L36: VIG | M36: 251.876.330
A37: 00095 | B37: ALMEIDA, ALMEIDA, ALMEIRA E ALMEIDA LTDA | C37: RUA DOS EXPEDICIONARIOS, 668 CX.P. 73 | D37: 73 | E37: CENTRO | F37: OURINHOS | G37: SP | H37: 53.418.257/0001-24 | I37: (14) 3326-1600 | J37: compras2.almeida@gmail.com | L37: ROMUALDO | M37: 495.005.602.110
A38: 00097 | B38: BRUSFER COMERCIO DE FERRAGENS LTDA. | C38: AV. OTTO RENAUX, | D38: 310 | E38: CENTRO | F38: BRUSQUE | G38: SC | H38: 00.442.819/0001-09 | I38: (47)3351-3423 | J38: compras@brusfer.com.br | K38: ST NORMAL ATE DEZ/2014 | L38: VIG | M38: 252.965.418
A39: 00098 | B39: BRUNETTI ABRASIVOS E SOLDA LTDA. | C39: AV. SILVIO AVIDOS, | D39: 221 | E39: SAO SILVANO | F39: COLATINA | G39: ES | H39: 31.755.812/0001-70 | I39: (27)3721-3380 | J39: brunettiabras@hotmail.com | L39: ARISTOTELES - ARI REPR.ES | M39: 081.221.037
A40: 00100 | B40: COMPRESSORES E MAQUINAS LTDA | C40: RUA P 7, QD. P 77 LOTE 03 | D40: 215 | E40: SETOR DOS FUNCIONARI | F40: GOIANIA | G40: GO | H40: 02.374.124/0001-62 | I40: (62)32337198 | J40: atlantecnica@terra.com.br | L40: ENIO SILVA | M40: 10.301.633.3
...
